<?xml version="1.0" encoding="UTF-8"?>
<testng-results ignored="0" total="1" passed="1" failed="0" skipped="0">
  <reporter-output>
  </reporter-output>
  <suite started-at="2022-03-31T14:36:31 IST" name="Default suite" finished-at="2022-03-31T14:36:48 IST" duration-ms="17308">
    <groups>
    </groups>
    <test started-at="2022-03-31T14:36:31 IST" name="Default test" finished-at="2022-03-31T14:36:48 IST" duration-ms="17308">
      <class name="testing1.Task2">
        <test-method is-config="true" signature="SetDriver()[pri:0, instance:testing1.Task2@31e5415e]" started-at="2022-03-31T14:36:31 IST" name="SetDriver" finished-at="2022-03-31T14:36:48 IST" duration-ms="16976" status="PASS">
          <reporter-output>
          </reporter-output>
        </test-method> <!-- SetDriver -->
        <test-method signature="Test()[pri:0, instance:testing1.Task2@31e5415e]" started-at="2022-03-31T14:36:48 IST" name="Test" finished-at="2022-03-31T14:36:48 IST" duration-ms="185" status="PASS">
          <reporter-output>
          </reporter-output>
        </test-method> <!-- Test -->
        <test-method is-config="true" signature="closedriver()[pri:0, instance:testing1.Task2@31e5415e]" started-at="2022-03-31T14:36:48 IST" name="closedriver" finished-at="2022-03-31T14:36:48 IST" duration-ms="93" status="FAIL">
          <exception class="java.lang.AssertionError">
            <message>
              <![CDATA[expected [39℃] but found [39?]]]>
            </message>
            <full-stacktrace>
              <![CDATA[java.lang.AssertionError: expected [39℃] but found [39?]
at org.testng.Assert.fail(Assert.java:99)
at org.testng.Assert.failNotEquals(Assert.java:1037)
at org.testng.Assert.assertEqualsImpl(Assert.java:140)
at org.testng.Assert.assertEquals(Assert.java:122)
at org.testng.Assert.assertEquals(Assert.java:629)
at org.testng.Assert.assertEquals(Assert.java:639)
at testing.Task1.closedriver(Task1.java:30)
at java.base/jdk.internal.reflect.NativeMethodAccessorImpl.invoke0(Native Method)
at java.base/jdk.internal.reflect.NativeMethodAccessorImpl.invoke(NativeMethodAccessorImpl.java:62)
at java.base/jdk.internal.reflect.DelegatingMethodAccessorImpl.invoke(DelegatingMethodAccessorImpl.java:43)
at java.base/java.lang.reflect.Method.invoke(Method.java:566)
at org.testng.internal.MethodInvocationHelper.invokeMethod(MethodInvocationHelper.java:133)
at org.testng.internal.MethodInvocationHelper.invokeMethodConsideringTimeout(MethodInvocationHelper.java:62)
at org.testng.internal.ConfigInvoker.invokeConfigurationMethod(ConfigInvoker.java:385)
at org.testng.internal.ConfigInvoker.invokeConfigurations(ConfigInvoker.java:321)
at org.testng.TestRunner.invokeTestConfigurations(TestRunner.java:637)
at org.testng.TestRunner.afterRun(TestRunner.java:877)
at org.testng.TestRunner.run(TestRunner.java:599)
at org.testng.SuiteRunner.runTest(SuiteRunner.java:377)
at org.testng.SuiteRunner.runSequentially(SuiteRunner.java:371)
at org.testng.SuiteRunner.privateRun(SuiteRunner.java:332)
at org.testng.SuiteRunner.run(SuiteRunner.java:276)
at org.testng.SuiteRunnerWorker.runSuite(SuiteRunnerWorker.java:53)
at org.testng.SuiteRunnerWorker.run(SuiteRunnerWorker.java:96)
at org.testng.TestNG.runSuitesSequentially(TestNG.java:1212)
at org.testng.TestNG.runSuitesLocally(TestNG.java:1134)
at org.testng.TestNG.runSuites(TestNG.java:1063)
at org.testng.TestNG.run(TestNG.java:1031)
at org.testng.remote.AbstractRemoteTestNG.run(AbstractRemoteTestNG.java:115)
at org.testng.remote.RemoteTestNG.initAndRun(RemoteTestNG.java:251)
at org.testng.remote.RemoteTestNG.main(RemoteTestNG.java:77)
]]>
            </full-stacktrace>
          </exception> <!-- java.lang.AssertionError -->
          <reporter-output>
          </reporter-output>
        </test-method> <!-- closedriver -->
      </class> <!-- testing1.Task2 -->
    </test> <!-- Default test -->
  </suite> <!-- Default suite -->
</testng-results>
